Workbook

Sheet Work Queue
A1: Work Queue - counts update automatically from All Claims - Draft
A3: Follow-up Status | B3: Claims | D3: How to use
A4: OVERDUE | B4: =COUNTIF('All Claims - Draft'!$BF:$BF,A4) -> 132 | D4: • Orange headers on All Claims = columns you type in. Navy = report data. Grey = helper formulas (don't type there).
A5: Due within 7 days | B5: =COUNTIF('All Claims - Draft'!$BF:$BF,A5) -> 27 | D5: • Filter "Follow-up Status" = OVERDUE to get today's worklist.
A6: No review date set | B6: =COUNTIF('All Claims - Draft'!$BF:$BF,A6) -> 62 | D6: • Filter "Missing Info" (non-blank) to see what each claim still needs.
A7: Scheduled | B7: =COUNTIF('All Claims - Draft'!$BF:$BF,A7) -> 77 | D7: • "Suggested Denial Reason" reads the Denial Code; "Suggested Next Step" reads the Denial Reason.
A8: Closed | B8: =COUNTIF('All Claims - Draft'!$BF:$BF,A8) -> 195 | D8: • Dropdowns are on Claim Status, Last Action, Denial Reason, Denial Code and both Adjustment Code columns; you can still type a value not on the list.
D9: • See the Change Log tab for every cell changed when this copy was made.
A10: Claim Status | B10: Claims
A11: Finalized | B11: =COUNTIF('All Claims - Draft'!$A:$A,A11) -> 195
A12: Denied | B12: =COUNTIF('All Claims - Draft'!$A:$A,A12) -> 163
A13: Under Review | B13: =COUNTIF('All Claims - Draft'!$A:$A,A13) -> 51
A14: Pending | B14: =COUNTIF('All Claims - Draft'!$A:$A,A14) -> 39
A15: PAID | B15: =COUNTIF('All Claims - Draft'!$A:$A,A15) -> 23
A16: Rejected | B16: =COUNTIF('All Claims - Draft'!$A:$A,A16) -> 15
A17: Received | B17: =COUNTIF('All Claims - Draft'!$A:$A,A17) -> 4
A18: Not found | B18: =COUNTIF('All Claims - Draft'!$A:$A,A18) -> 3
A20: Claims missing this field | B20: Claims
A21: Notes | B21: =COUNTIF('All Claims - Draft'!$BH:$BH,"*"&A21&"*") -> 31
A22: Latest Date Worked | B22: =COUNTIF('All Claims - Draft'!$BH:$BH,"*"&A22&"*") -> 61
A23: Last Action | B23: =COUNTIF('All Claims - Draft'!$BH:$BH,"*"&A23&"*") -> 53
A24: Denial Reason | B24: =COUNTIF('All Claims - Draft'!$BH:$BH,"*"&A24&"*") -> 8
A25: Denial Code | B25: =COUNTIF('All Claims - Draft'!$BH:$BH,"*"&A25&"*") -> 69
A26: Next Review Date | B26: =COUNTIF('All Claims - Draft'!$BH:$BH,"*"&A26&"*") -> 62
A27: Next Step | B27: =COUNTIF('All Claims - Draft'!$BH:$BH,"*"&A27&"*") -> 198
A28: CPT outcome | B28: =COUNTIF('All Claims - Draft'!$BH:$BH,"*"&A28&"*") -> 7
A30: Open claims by Denial Reason (not Finalized) | B30: Claims
A31: No authorization | B31: =COUNTIFS('All Claims - Draft'!$BA:$BA,A31&"*",'All Claims - Draft'!$A:$A,"<>Finalized") -> 19
A32: Timely filing | B32: =COUNTIFS('All Claims - Draft'!$BA:$BA,A32&"*",'All Claims - Draft'!$A:$A,"<>Finalized") -> 3
A33: Medical records needed | B33: =COUNTIFS('All Claims - Draft'!$BA:$BA,A33&"*",'All Claims - Draft'!$A:$A,"<>Finalized") -> 45
A34: Bundled / NCCI edit | B34: =COUNTIFS('All Claims - Draft'!$BA:$BA,A34&"*",'All Claims - Draft'!$A:$A,"<>Finalized") -> 21
A35: Modifier issue | B35: =COUNTIFS('All Claims - Draft'!$BA:$BA,A35&"*",'All Claims - Draft'!$A:$A,"<>Finalized") -> 10
A36: Diagnosis issue | B36: =COUNTIFS('All Claims - Draft'!$BA:$BA,A36&"*",'All Claims - Draft'!$A:$A,"<>Finalized") -> 4
A37: Coding / billing error | B37: =COUNTIFS('All Claims - Draft'!$BA:$BA,A37&"*",'All Claims - Draft'!$A:$A,"<>Finalized") -> 16
A38: Not covered by plan | B38: =COUNTIFS('All Claims - Draft'!$BA:$BA,A38&"*",'All Claims - Draft'!$A:$A,"<>Finalized") -> 3
A39: Not covered by secondary | B39: =COUNTIFS('All Claims - Draft'!$BA:$BA,A39&"*",'All Claims - Draft'!$A:$A,"<>Finalized") -> 0
A40: Medical necessity / frequency | B40: =COUNTIFS('All Claims - Draft'!$BA:$BA,A40&"*",'All Claims - Draft'!$A:$A,"<>Finalized") -> 8
A41: Wrong payer / vendor | B41: =COUNTIFS('All Claims - Draft'!$BA:$BA,A41&"*",'All Claims - Draft'!$A:$A,"<>Finalized") -> 22
A42: Other insurance / COB | B42: =COUNTIFS('All Claims - Draft'!$BA:$BA,A42&"*",'All Claims - Draft'!$A:$A,"<>Finalized") -> 11
... A52: Other | B52: =COUNTIFS('All Claims - Draft'!$BA:$BA,A52&"*",'All Claims - Draft'!$A:$A,"<>Finalized") -> 13

Sheet All Claims - Draft
A1: Claim Status | B1: Notes | C1: Primary Claim ID | D1: Processed Date | E1: Chart Number | F1: Date of Service | G1: Responsible Payer | H1: Primary Payer Name | I1: Secondary Payer Name | J1: Procedure Code | K1: Latest Date Worked | L1: Days Until Deadline | M1: Days Until Corrected Claim Deadline | N1: Days Until Appeal Deadline | O1: Filing Deadline | P1: Filing Limit | Q1: Limit Carrier | R1: Corrected Claim Limit | S1: Corrected Claim From | T1: Appeal Limit | U1: Appeal From | V1: Service Month | W1: Specialty | X1: Modifier 1 | Y1: Modifier 2 | Z1: Modifier 3 | AA1: Units | AB1: AR Age by Service Date | AC1: Procedure Code 1 | AD1: Procedure Code 2 | AE1: Procedure Code 3 | AF1: Procedure Code 4 | AG1: Procedure Code 5 | AH1: Procedure Code 6 | AI1: Procedure Code 7 | AJ1: Diagnosis Code 1 | AK1: Diagnosis Code 2 | AL1: Diagnosis Code 3 | AM1: Diagnosis Code 4 | AN1: Secondary Claim ID | AO1: Rendering Provider | AP1: Location Name | AQ1: Created Date | AR1: CPT Codes Adjusted (not payable) | AS1: Adjustment Code | AT1: CPT Codes Adjusted (payable) | AU1: Adjustment Code (payable) | AV1: CPT Codes Paid | AW1: CPT Codes Worked - Adjusted | AX1: CPT Codes Worked | AY1: Last Action | AZ1: Prior Actions | BA1: Denial Reason | BB1: Denial Code | BC1: Reference # | BD1: Next Review Date | BE1: Next Step | BF1: Follow-up Status | BG1: Days Since Worked | BH1: Missing Info | BI1: Suggested Denial Reason (from code) | BJ1: Suggested Next Step (from reason)
A2: PAID | B2: OP | C2: 546185672 | D2: 46252 | E2: HF514237620 | F2: 46035 | G2: Aetna Legacy | H2: DME Region D | I2: Aetna Legacy | J2: A6023+A1 x10 | L2: =IF($O2="","",$O2-TODAY()) -> 89 | M2: =IF(AND(TRIM($A2)="Finalized",$K2<>""),"",IF($D2="","",$D2+365-TODAY())) -> 306 | N2: =IF(AND(TRIM($A2)="Finalized",$K2<>""),"",IF($D2="","",$D2+120-TODAY())) -> 61 | O2: =IF(AND(TRIM($A2)="Finalized",$K2<>""),"",DATE(2027,1,13)) -> 46400 | P2: 365 days | Q2: MEDICARE | R2: 365 days | S2: Processed date | T2: 120 days | U2: Processed date | V2: 2026-01 January | W2: DME | X2: A1 | AA2: 10 | AB2: =IF($F2="","",TODAY()-$F2) -> 276 | AC2: A6023 | AJ2: G894 | AK2: M48062 | AN2: 552888745 | AO2: Advanced Spine and Pain LLC DME SUR | AP2: Advanced Spine and Pain LLC DME - Surprise Reems | AQ2: 46036 | BF2: =IF(TRIM($A2)="Finalized","Closed",IF($BD2="","No review date set",IF($BD2<TODAY(),"OVERDUE",IF($BD2-TODAY()<=7,"Due within 7 days","Scheduled")))) -> No review date set | BG2: =IF($K2="","",TODAY()-$K2) | BH2: =IFERROR(LEFT(IF($B2="","Notes, ","")&IF($K2="","Latest Date Worked, ","")&IF($AY2="","Last Action, ","")&IF(AND(OR(TRIM($A2)="Denied",TRIM($A2)="Rejected"),$BA2=""),"Denial Reason, ","")&IF(AND(TRIM($A2)="Denied",$BB2="",TRIM($BA2)<>"NO DENIAL"),"Denial Code, ","")&IF(AND(TRIM($A2)<>"Finalized",$BD2=""),"Next Review Date, ","")&IF(AND(TRIM($A2)<>"Finalized",$BE2=""),"Next Step, ","")&IF(AND(TRIM($A2)="Finalized",$AV2="",$AR2="",$AT2="",$AX2="",$AW2=""),"CPT outcome, ",""),LEN(IF($B2="","Notes, ","")&IF($K2="","Latest Date Worked, ","")&IF($AY2="","Last Action, ","")&IF(AND(OR(TRIM($A2)="Denied",TRIM($A2)="Rejected"),$BA2=""),"Denial Reason, ","")&IF(AND(TRIM($A2)="Denied",$BB2="",TRIM($BA2)<>"NO DENIAL"),"Denial Code, ","")&IF(AND(TRIM($A2)<>"Finalized",$BD2=""),"Next Review Date, ","")&IF(AND(TRIM($A2)<>"Finalized",$BE2=""),"Next Step, ","")&IF(AND(TRIM($A2)="Finalized",$AV2="",$AR2="",$AT2="",$AX2="",$AW2=""),"CPT outcome, ",""))-2),"") -> Latest Date Worked, Last Action, Next Review Date, Next Step | BI2: =IF($BB2="","",IFERROR(INDEX('Denial Codes'!$C:$C,MATCH(LEFT($BB2,FIND(" - ",$BB2&" - ")+2)&"*",'Denial Codes'!$A:$A,0)),"")) | BJ2: =IF($BA2="","",IFERROR(INDEX(Lists!$B:$B,MATCH(TRIM($BA2),Lists!$A:$A,0))&"",""))
A3: Under Review | C3: 569224437 | E3: HF450934372 | F3: 46044 | G3: Gold Kidney Health Plan | H3: Gold Kidney Health Plan | I3: No Payer | J3: 22845+58+59 x1; 22853+58+59 x1; 22853+58 x1; 22845+58+59 x1 | L3: =IF($O3="","",$O3-TODAY()) | Q3: Not on reference list | V3: 2026-01 January | W3: ORTHO | X3: 58 | Y3: 59 | AA3: 4 | AB3: =IF($F3="","",TODAY()-$F3) -> 267 | AC3: 22845 | AD3: 22853 | AE3: 22853 | AF3: 22845 | AJ3: M4316 | AK3: M5416 | AO3: MAYURAN, VIKRAM | AP3: Banner Desert Medical Center | AQ3: 46254 | BE3: Check Gold Kidney portal once the account is reactivated | BF3: =IF(TRIM($A3)="Finalized","Closed",IF($BD3="","No review date set",IF($BD3<TODAY(),"OVERDUE",IF($BD3-TODAY()<=7,"Due within 7 days","Scheduled")))) -> No review date set | BG3: =IF($K3="","",TODAY()-$K3) | BH3: =IFERROR(LEFT(IF($B3="","Notes, ","")&IF($K3="","Latest Date Worked, ","")&IF($AY3="","Last Action, ","")&IF(AND(OR(TRIM($A3)="Denied",TRIM($A3)="Rejected"),$BA3=""),"Denial Reason, ","")&IF(AND(TRIM($A3)="Denied",$BB3="",TRIM($BA3)<>"NO DENIAL"),"Denial Code, ","")&IF(AND(TRIM($A3)<>"Finalized",$BD3=""),"Next Review Date, ","")&IF(AND(TRIM($A3)<>"Finalized",$BE3=""),"Next Step, ","")&IF(AND(TRIM($A3)="Finalized",$AV3="",$AR3="",$AT3="",$AX3="",$AW3=""),"CPT outcome, ",""),LEN(IF($B3="","Notes, ","")&IF($K3="","Latest Date Worked, ","")&IF($AY3="","Last Action, ","")&IF(AND(OR(TRIM($A3)="Denied",TRIM($A3)="Rejected"),$BA3=""),"Denial Reason, ","")&IF(AND(TRIM($A3)="Denied",$BB3="",TRIM($BA3)<>"NO DENIAL"),"Denial Code, ","")&IF(AND(TRIM($A3)<>"Finalized",$BD3=""),"Next Review Date, ","")&IF(AND(TRIM($A3)<>"Finalized",$BE3=""),"Next Step, ","")&IF(AND(TRIM($A3)="Finalized",$AV3="",$AR3="",$AT3="",$AX3="",$AW3=""),"CPT outcome, ",""))-2),"") -> Notes, Latest Date Worked, Last Action, Next Review Date | BI3: =IF($BB3="","",IFERROR(INDEX('Denial Codes'!$C:$C,MATCH(LEFT($BB3,FIND(" - ",$BB3&" - ")+2)&"*",'Denial Codes'!$A:$A,0)),"")) | BJ3: =IF($BA3="","",IFERROR(INDEX(Lists!$B:$B,MATCH(TRIM($BA3),Lists!$A:$A,0))&"",""))
A4: Denied | B4: Added anatomical modifiers, and resubmitted | C4: 555920273 | D4: 46247 | E4: HF548529635 | F4: 46079 | G4: Mercy Care Plan (AHCCCS) - Complete Care & Long Term Care (LTC) | H4: Mercy Care Plan (AHCCCS) - Complete Care & Long Term Care (LTC) | I4: No Payer | J4: L3916+NU x1; L3916+NU x1 | K4: 46310 | L4: =IF($O4="","",$O4-TODAY()) -> -52 | M4: =IF(AND(TRIM($A4)="Finalized",$K4<>""),"",IF($F4="","",$F4+365-TODAY())) -> 133 | N4: =IF(AND(TRIM($A4)="Finalized",$K4<>""),"",IF($F4="","",$F4+365-TODAY())) -> 133 | O4: =IF(AND(TRIM($A4)="Finalized",$K4<>""),"",DATE(2026,8,25)) -> 46259 | P4: 180 days | Q4: MERCY CARE MEDICAID | R4: 365 days | S4: Date of service | T4: 365 days | U4: Date of service | V4: 2026-02 February | W4: DME | X4: NU | AA4: 2 | AB4: =IF($F4="","",TODAY()-$F4) -> 232 | AC4: L3916 | AD4: L3916 | AJ4: M19031, M19032 | AO4: Arshad, Jawad | AP4: ASAP - Mesa | AQ4: 46084 | AV4: L3916+RT | AX4: L3916+LT | AY4: Resubmitted | AZ4: Resubmitted | BA4: Modifier issue | BB4: CO_18 - Exact duplicate claim/service | BF4: =IF(TRIM($A4)="Finalized","Closed",IF($BD4="","No review date set",IF($BD4<TODAY(),"OVERDUE",IF($BD4-TODAY()<=7,"Due within 7 days","Scheduled")))) -> No review date set | BG4: =IF($K4="","",TODAY()-$K4) -> 1 | BH4: =IFERROR(LEFT(IF($B4="","Notes, ","")&IF($K4="","Latest Date Worked, ","")&IF($AY4="","Last Action, ","")&IF(AND(OR(TRIM($A4)="Denied",TRIM($A4)="Rejected"),$BA4=""),"Denial Reason, ","")&IF(AND(TRIM($A4)="Denied",$BB4="",TRIM($BA4)<>"NO DENIAL"),"Denial Code, ","")&IF(AND(TRIM($A4)<>"Finalized",$BD4=""),"Next Review Date, ","")&IF(AND(TRIM($A4)<>"Finalized",$BE4=""),"Next Step, ","")&IF(AND(TRIM($A4)="Finalized",$AV4="",$AR4="",$AT4="",$AX4="",$AW4=""),"CPT outcome, ",""),LEN(IF($B4="","Notes, ","")&IF($K4="","Latest Date Worked, ","")&IF($AY4="","Last Action, ","")&IF(AND(OR(TRIM($A4)="Denied",TRIM($A4)="Rejected"),$BA4=""),"Denial Reason, ","")&IF(AND(TRIM($A4)="Denied",$BB4="",TRIM($BA4)<>"NO DENIAL"),"Denial Code, ","")&IF(AND(TRIM($A4)<>"Finalized",$BD4=""),"Next Review Date, ","")&IF(AND(TRIM($A4)<>"Finalized",$BE4=""),"Next Step, ","")&IF(AND(TRIM($A4)="Finalized",$AV4="",$AR4="",$AT4="",$AX4="",$AW4=""),"CPT outcome, ",""))-2),"") -> Next Review Date, Next Step | BI4: =IF($BB4="","",IFERROR(INDEX('Denial Codes'!$C:$C,MATCH(LEFT($BB4,FIND(" - ",$BB4&" - ")+2)&"*",'Denial Codes'!$A:$A,0)),"")) -> Duplicate claim | BJ4: =IF($BA4="","",IFERROR(INDEX(Lists!$B:$B,MATCH(TRIM($BA4),Lists!$A:$A,0))&"","")) -> Correct or add the modifier (e.g. NU/RR, KX, RT/LT, 25) and resubmit.
A5: Rejected | B5: Provider TAX ID/NPI Combination is not on file with BCBS AZ | C5: 552282138 | E5: HF527802572 | F5: 46085 | G5: Blue Cross Blue Shield of Arizona (BCBS AZ) | H5: Blue Cross Blue Shield of Arizona (BCBS AZ) | I5: No Payer | J5: 63045 x1; 63048 x1 | K5: 46310 | L5: =IF($O5="","",$O5-TODAY()) -> -136 | M5: =IF(AND(TRIM($A5)="Finalized",$K5<>""),"",IF($F5="","",$F5+90-TODAY())) -> -136 | N5: =IF(AND(TRIM($A5)="Finalized",$K5<>""),"",IF($D5="","",$D5+365-TODAY())) | O5: =IF(AND(TRIM($A5)="Finalized",$K5<>""),"",DATE(2026,6,2)) -> 46175 | P5: 90 days | Q5: BCBS | R5: 90 days | S5: Date of service | T5: 365 days | U5: Processed date | V5: 2026-03 March | W5: ORTHO | AA5: 2 | AB5: =IF($F5="","",TODAY()-$F5) -> 226 | AC5: 63045 | AD5: 63048 | AJ5: M5412 | AK5: M5010 | AL5: M4722 | AM5: M960 | AO5: MCCUNNIFF, PETER | AP5: ASAP Surgery Centers North Valley LLC | AQ5: 46273 | AX5: 63045, 63048 | AY5: Resubmitted | BA5: Credentialing / out of network | BB5: N290 - Missing/incomplete/invalid rendering provider primary identifier | BD5: 46314 | BF5: =IF(TRIM($A5)="Finalized","Closed",IF($BD5="","No review date set",IF($BD5<TODAY(),"OVERDUE",IF($BD5-TODAY()<=7,"Due within 7 days","Scheduled")))) -> Due within 7 days | BG5: =IF($K5="","",TODAY()-$K5) -> 1 | BH5: =IFERROR(LEFT(IF($B5="","Notes, ","")&IF($K5="","Latest Date Worked, ","")&IF($AY5="","Last Action, ","")&IF(AND(OR(TRIM($A5)="Denied",TRIM($A5)="Rejected"),$BA5=""),"Denial Reason, ","")&IF(AND(TRIM($A5)="Denied",$BB5="",TRIM($BA5)<>"NO DENIAL"),"Denial Code, ","")&IF(AND(TRIM($A5)<>"Finalized",$BD5=""),"Next Review Date, ","")&IF(AND(TRIM($A5)<>"Finalized",$BE5=""),"Next Step, ","")&IF(AND(TRIM($A5)="Finalized",$AV5="",$AR5="",$AT5="",$AX5="",$AW5=""),"CPT outcome, ",""),LEN(IF($B5="","Notes, ","")&IF($K5="","Latest Date Worked, ","")&IF($AY5="","Last Action, ","")&IF(AND(OR(TRIM($A5)="Denied",TRIM($A5)="Rejected"),$BA5=""),"Denial Reason, ","")&IF(AND(TRIM($A5)="Denied",$BB5="",TRIM($BA5)<>"NO DENIAL"),"Denial Code, ","")&IF(AND(TRIM($A5)<>"Finalized",$BD5=""),"Next Review Date, ","")&IF(AND(TRIM($A5)<>"Finalized",$BE5=""),"Next Step, ","")&IF(AND(TRIM($A5)="Finalized",$AV5="",$AR5="",$AT5="",$AX5="",$AW5=""),"CPT outcome, ",""))-2),"") -> Next Step | BI5: =IF($BB5="","",IFERROR(INDEX('Denial Codes'!$C:$C,MATCH(LEFT($BB5,FIND(" - ",$BB5&" - ")+2)&"*",'Denial Codes'!$A:$A,0)),"")) -> Credentialing / out of network | BJ5: =IF($BA5="","",IFERROR(INDEX(Lists!$B:$B,MATCH(TRIM($BA5),Lists!$A:$A,0))&"","")) -> Check provider enrollment, NPI/TIN and network status; appeal once credentialing is confirmed.
A6: Denied | B6: Resubmitted to primary plan Arizona Ufcw Employers Health | C6: 552709009 | D6: 46261 | E6: HF507623401 | F6: 46093 | G6: United Healthcare | H6: United Healthcare | I6: No Payer | J6: 99494 x1; 99492 x1 | K6: 46310 | L6: =IF($O6="","",$O6-TODAY()) -> -128 | M6: =IF(AND(TRIM($A6)="Finalized",$K6<>""),"",IF($D6="","",$D6+180-TODAY())) -> 130 | N6: =IF(AND(TRIM($A6)="Finalized",$K6<>""),"",IF($D6="","",$D6+365-TODAY())) -> 315 | O6: =IF(AND(TRIM($A6)="Finalized",$K6<>""),"",DATE(2026,6,10)) -> 46183 | P6: 90 days | Q6: UHC COMMERCIAL | R6: 180 days | S6: Processed date | T6: 365 days | U6: Processed date | V6: 2026-03 March | W6: BH | AA6: 2 | AB6: =IF($F6="","",TODAY()-$F6) -> 218 | AC6: 99494 | AD6: 99492 | AJ6: F1190 | AO6: MORALES, DAVID | AP6: ASAP - DEER VALLEY | AQ6: 46119 | AX6: 99492, 99494 | AY6: Resubmitted | BA6: Other insurance / COB | BB6: OA_22 - This care may be covered by another payer per coordination of benefits | BD6: 46341 | BF6: =IF(TRIM($A6)="Finalized","Closed",IF($BD6="","No review date set",IF($BD6<TODAY(),"OVERDUE",IF($BD6-TODAY()<=7,"Due within 7 days","Scheduled")))) -> Scheduled | BG6: =IF($K6="","",TODAY()-$K6) -> 1 | BH6: =IFERROR(LEFT(IF($B6="","Notes, ","")&IF($K6="","Latest Date Worked, ","")&IF($AY6="","Last Action, ","")&IF(AND(OR(TRIM($A6)="Denied",TRIM($A6)="Rejected"),$BA6=""),"Denial Reason, ","")&IF(AND(TRIM($A6)="Denied",$BB6="",TRIM($BA6)<>"NO DENIAL"),"Denial Code, ","")&IF(AND(TRIM($A6)<>"Finalized",$BD6=""),"Next Review Date, ","")&IF(AND(TRIM($A6)<>"Finalized",$BE6=""),"Next Step, ","")&IF(AND(TRIM($A6)="Finalized",$AV6="",$AR6="",$AT6="",$AX6="",$AW6=""),"CPT outcome, ",""),LEN(IF($B6="","Notes, ","")&IF($K6="","Latest Date Worked, ","")&IF($AY6="","Last Action, ","")&IF(AND(OR(TRIM($A6)="Denied",TRIM($A6)="Rejected"),$BA6=""),"Denial Reason, ","")&IF(AND(TRIM($A6)="Denied",$BB6="",TRIM($BA6)<>"NO DENIAL"),"Denial Code, ","")&IF(AND(TRIM($A6)<>"Finalized",$BD6=""),"Next Review Date, ","")&IF(AND(TRIM($A6)<>"Finalized",$BE6=""),"Next Step, ","")&IF(AND(TRIM($A6)="Finalized",$AV6="",$AR6="",$AT6="",$AX6="",$AW6=""),"CPT outcome, ",""))-2),"") -> Next Step | BI6: =IF($BB6="","",IFERROR(INDEX('Denial Codes'!$C:$C,MATCH(LEFT($BB6,FIND(" - ",$BB6&" - ")+2)&"*",'Denial Codes'!$A:$A,0)),"")) -> Other insurance / COB | BJ6: =IF($BA6="","",IFERROR(INDEX(Lists!$B:$B,MATCH(TRIM($BA6),Lists!$A:$A,0))&"","")) -> Get the other insurance and primary EOB, update COB with the payer and bill primary first.
A7: Denied | B7: Uploaded MR - Transaction Submission Confirmation Case ID# 18151 | C7: 568271516 | D7: 46261 | E7: HF532203609 | F7: 46105 | G7: UMR Wausau / UHIS | H7: UMR Wausau / UHIS | I7: No Payer | J7: 93970 x1 | K7: 46310 | L7: =IF($O7="","",$O7-TODAY()) | N7: =IF(AND(TRIM($A7)="Finalized",$K7<>""),"",IF($D7="","",$D7+180-TODAY())) -> 130 | Q7: UMR / WAUSAU | T7: 180 days | U7: Processed date | V7: 2026-03 March | W7: US | AA7: 1 | AB7: =IF($F7="","",TODAY()-$F7) -> 206 | AC7: 93970 | AJ7: I10 | AK7: R2243 | AO7: LEATHEM, JARRETT | AP7: ASAP - Gilbert | AQ7: 46245 | AX7: 93970 | AY7: Uploaded MR | BA7: Medical records needed | BB7: CO_252 - An attachment/other documentation is required to adjudicate this claim/service | BC7: Case ID# 18151 | BD7: 46341 | BF7: =IF(TRIM($A7)="Finalized","Closed",IF($BD7="","No review date set",IF($BD7<TODAY(),"OVERDUE",IF($BD7-TODAY()<=7,"Due within 7 days","Scheduled")))) -> Scheduled | BG7: =IF($K7="","",TODAY()-$K7) -> 1 | BH7: =IFERROR(LEFT(IF($B7="","Notes, ","")&IF($K7="","Latest Date Worked, ","")&IF($AY7="","Last Action, ","")&IF(AND(OR(TRIM($A7)="Denied",TRIM($A7)="Rejected"),$BA7=""),"Denial Reason, ","")&IF(AND(TRIM($A7)="Denied",$BB7="",TRIM($BA7)<>"NO DENIAL"),"Denial Code, ","")&IF(AND(TRIM($A7)<>"Finalized",$BD7=""),"Next Review Date, ","")&IF(AND(TRIM($A7)<>"Finalized",$BE7=""),"Next Step, ","")&IF(AND(TRIM($A7)="Finalized",$AV7="",$AR7="",$AT7="",$AX7="",$AW7=""),"CPT outcome, ",""),LEN(IF($B7="","Notes, ","")&IF($K7="","Latest Date Worked, ","")&IF($AY7="","Last Action, ","")&IF(AND(OR(TRIM($A7)="Denied",TRIM($A7)="Rejected"),$BA7=""),"Denial Reason, ","")&IF(AND(TRIM($A7)="Denied",$BB7="",TRIM($BA7)<>"NO DENIAL"),"Denial Code, ","")&IF(AND(TRIM($A7)<>"Finalized",$BD7=""),"Next Review Date, ","")&IF(AND(TRIM($A7)<>"Finalized",$BE7=""),"Next Step, ","")&IF(AND(TRIM($A7)="Finalized",$AV7="",$AR7="",$AT7="",$AX7="",$AW7=""),"CPT outcome, ",""))-2),"") -> Next Step | BI7: =IF($BB7="","",IFERROR(INDEX('Denial Codes'!$C:$C,MATCH(LEFT($BB7,FIND(" - ",$BB7&" - ")+2)&"*",'Denial Codes'!$A:$A,0)),"")) -> Medical records needed | BJ7: =IF($BA7="","",IFERROR(INDEX(Lists!$B:$B,MATCH(TRIM($BA7),Lists!$A:$A,0))&"","")) -> Upload the MR on the payer portal, note the PIQ/reference number and set a review date.
A8: Denied | B8: Added mod 24, and resubmitted - DND Proc 99493 is included in the global period of HxProc 64635 on Claim ID RC2772466500 Line ID 1 on date of service 03/24/2026. | C8: 554160244 | D8: 46266 | E8: HF523425107 | F8: 46106 | G8: UnitedHealthcare Community Plan / Arizona Long Term Care | H8: UnitedHealthcare Community Plan / Arizona Long Term Care | I8: No Payer | J8: 99494 x1; 99493 x1 | K8: 46310 | L8: =IF($O8="","",$O8-TODAY()) -> -115 | M8: =IF(AND(TRIM($A8)="Finalized",$K8<>""),"",IF($D8="","",$D8+180-TODAY())) -> 135 | N8: =IF(AND(TRIM($A8)="Finalized",$K8<>""),"",IF($D8="","",$D8+365-TODAY())) -> 320 | O8: =IF(AND(TRIM($A8)="Finalized",$K8<>""),"",DATE(2026,6,23)) -> 46196 | P8: 90 days | Q8: UHC COMMUNITY | R8: 180 days | S8: Processed date | T8: 365 days | U8: Processed date | V8: 2026-03 March | W8: BH | AA8: 2 | AB8: =IF($F8="","",TODAY()-$F8) -> 205 | AC8: 99494 | AD8: 99493 | AJ8: F4323 | AO8: TURLEY, TODD | AP8: ASAP - DEER VALLEY | AQ8: 46119 | AX8: 99493, 99494 | AY8: Resubmitted | BA8: Bundled / NCCI edit | BB8: CO_97 - The benefit for this service is included in the payment/allowance for another service/procedure already adjudicated | BD8: 46341 | BF8: =IF(TRIM($A8)="Finalized","Closed",IF($BD8="","No review date set",IF($BD8<TODAY(),"OVERDUE",IF($BD8-TODAY()<=7,"Due within 7 days","Scheduled")))) -> Scheduled | BG8: =IF($K8="","",TODAY()-$K8) -> 1 | BH8: =IFERROR(LEFT(IF($B8="","Notes, ","")&IF($K8="","Latest Date Worked, ","")&IF($AY8="","Last Action, ","")&IF(AND(OR(TRIM($A8)="Denied",TRIM($A8)="Rejected"),$BA8=""),"Denial Reason, ","")&IF(AND(TRIM($A8)="Denied",$BB8="",TRIM($BA8)<>"NO DENIAL"),"Denial Code, ","")&IF(AND(TRIM($A8)<>"Finalized",$BD8=""),"Next Review Date, ","")&IF(AND(TRIM($A8)<>"Finalized",$BE8=""),"Next Step, ","")&IF(AND(TRIM($A8)="Finalized",$AV8="",$AR8="",$AT8="",$AX8="",$AW8=""),"CPT outcome, ",""),LEN(IF($B8="","Notes, ","")&IF($K8="","Latest Date Worked, ","")&IF($AY8="","Last Action, ","")&IF(AND(OR(TRIM($A8)="Denied",TRIM($A8)="Rejected"),$BA8=""),"Denial Reason, ","")&IF(AND(TRIM($A8)="Denied",$BB8="",TRIM($BA8)<>"NO DENIAL"),"Denial Code, ","")&IF(AND(TRIM($A8)<>"Finalized",$BD8=""),"Next Review Date, ","")&IF(AND(TRIM($A8)<>"Finalized",$BE8=""),"Next Step, ","")&IF(AND(TRIM($A8)="Finalized",$AV8="",$AR8="",$AT8="",$AX8="",$AW8=""),"CPT outcome, ",""))-2),"") -> Next Step | BI8: =IF($BB8="","",IFERROR(INDEX('Denial Codes'!$C:$C,MATCH(LEFT($BB8,FIND(" - ",$BB8&" - ")+2)&"*",'Denial Codes'!$A:$A,0)),"")) -> Bundled / NCCI edit | BJ8: =IF($BA8="","",IFERROR(INDEX(Lists!$B:$B,MATCH(TRIM($BA8),Lists!$A:$A,0))&"","")) -> Check the NCCI pair; if the service was distinct, add 59/XU (or XS) and resubmit; otherwise adjust.
A9: Under Review | B9: I need to ask Juan for MR | C9: 568316185 | D9: 46254 | E9: HF452729341 | F9: 46114 | G9: HealthSpring Medicare Advantage | H9: HealthSpring Medicare Advantage | I9: No Payer | J9: 93925 x1 | L9: =IF($O9="","",$O9-TODAY()) -> -107 | M9: =IF(AND(TRIM($A9)="Finalized",$K9<>""),"",IF($F9="","",$F9+90-TODAY())) -> -107 | N9: =IF(AND(TRIM($A9)="Finalized",$K9<>""),"",IF($D9="","",$D9+180-TODAY())) -> 123 | O9: =IF(AND(TRIM($A9)="Finalized",$K9<>""),"",DATE(2026,7,1)) -> 46204 | P9: 90 days | Q9: CIGNA / CIGNA MEDICARE | R9: 90 days | S9: Date of service | T9: 180 days | U9: Processed date | V9: 2026-04 April | W9: US | AA9: 1 | AB9: =IF($F9="","",TODAY()-$F9) -> 197 | AC9: 93925 | AJ9: I70213 | AO9: TURLEY, TODD | AP9: ASAP - DEER VALLEY 240 | AQ9: 46245 | AX9: 93925 | BA9: Duplicate claim | BB9: CO_18 - Exact duplicate claim/service | BE9: I need to ask Juan for MR | BF9: =IF(TRIM($A9)="Finalized","Closed",IF($BD9="","No review date set",IF($BD9<TODAY(),"OVERDUE",IF($BD9-TODAY()<=7,"Due within 7 days","Scheduled")))) -> No review date set | BG9: =IF($K9="","",TODAY()-$K9) | BH9: =IFERROR(LEFT(IF($B9="","Notes, ","")&IF($K9="","Latest Date Worked, ","")&IF($AY9="","Last Action, ","")&IF(AND(OR(TRIM($A9)="Denied",TRIM($A9)="Rejected"),$BA9=""),"Denial Reason, ","")&IF(AND(TRIM($A9)="Denied",$BB9="",TRIM($BA9)<>"NO DENIAL"),"Denial Code, ","")&IF(AND(TRIM($A9)<>"Finalized",$BD9=""),"Next Review Date, ","")&IF(AND(TRIM($A9)<>"Finalized",$BE9=""),"Next Step, ","")&IF(AND(TRIM($A9)="Finalized",$AV9="",$AR9="",$AT9="",$AX9="",$AW9=""),"CPT outcome, ",""),LEN(IF($B9="","Notes, ","")&IF($K9="","Latest Date Worked, ","")&IF($AY9="","Last Action, ","")&IF(AND(OR(TRIM($A9)="Denied",TRIM($A9)="Rejected"),$BA9=""),"Denial Reason, ","")&IF(AND(TRIM($A9)="Denied",$BB9="",TRIM($BA9)<>"NO DENIAL"),"Denial Code, ","")&IF(AND(TRIM($A9)<>"Finalized",$BD9=""),"Next Review Date, ","")&IF(AND(TRIM($A9)<>"Finalized",$BE9=""),"Next Step, ","")&IF(AND(TRIM($A9)="Finalized",$AV9="",$AR9="",$AT9="",$AX9="",$AW9=""),"CPT outcome, ",""))-2),"") -> Latest Date Worked, Last Action, Next Review Date | BI9: =IF($BB9="","",IFERROR(INDEX('Denial Codes'!$C:$C,MATCH(LEFT($BB9,FIND(" - ",$BB9&" - ")+2)&"*",'Denial Codes'!$A:$A,0)),"")) -> Duplicate claim | BJ9: =IF($BA9="","",IFERROR(INDEX(Lists!$B:$B,MATCH(TRIM($BA9),Lists!$A:$A,0))&"","")) -> Check the status of the original claim; no resubmission needed if it was processed.
A10: Denied | B10: Waiting on full recoup to bill PT - ABN signed - Bundling with HHA episode on DOS - HOME HEALTH SCOTTSDALE, LLC NPI 1154898542 | C10: 556764523 | D10: 46231 | E10: HF541770771 | F10: 46121 | G10: Tricare for Life (All Regions) | H10: DME Region D | I10: Tricare for Life (All Regions) | J10: A6023+A2 x20 | K10: 46310 | L10: =IF($O10="","",$O10-TODAY()) -> 175 | M10: =IF(AND(TRIM($A10)="Finalized",$K10<>""),"",IF($D10="","",$D10+365-TODAY())) -> 285 | N10: =IF(AND(TRIM($A10)="Finalized",$K10<>""),"",IF($D10="","",$D10+120-TODAY())) -> 40 | O10: =IF(AND(TRIM($A10)="Finalized",$K10<>""),"",DATE(2027,4,9)) -> 46486 | P10: 365 days | Q10: MEDICARE | R10: 365 days | S10: Processed date | T10: 120 days | U10: Processed date | V10: 2026-04 April | W10: DME | X10: A2 | AA10: 20 | AB10: =IF($F10="","",TODAY()-$F10) -> 190 | AC10: A6023 | AJ10: G894 | AN10: 559829888 | AO10: Advanced Spine and Pain LLC DME PEO | AP10: Advanced Spine and Pain LLC DME - Peoria | AQ10: 46133 | AX10: A6023 | AY10: Waiting on payer | BA10: Bundled / NCCI edit | BB10: N88 Alert: This payment is being made conditionally. An HHA episode of care notice has been filed for this patient. When a patient is treated under a HHA episode of care, consolidated billing requires that certain therapy services and supplies, such as this, be included in the HHA's payment. This payment will need to be recouped from you if we establish that the patient is concurrently receiving treatment under a HHA episode of care. | BD10: 46341 | BE10: Waiting on full recoup to bill PT | BF10: =IF(TRIM($A10)="Finalized","Closed",IF($BD10="","No review date set",IF($BD10<TODAY(),"OVERDUE",IF($BD10-TODAY()<=7,"Due within 7 days","Scheduled")))) -> Scheduled | BG10: =IF($K10="","",TODAY()-$K10) -> 1 | BH10: =IFERROR(LEFT(IF($B10="","Notes, ","")&IF($K10="","Latest Date Worked, ","")&IF($AY10="","Last Action, ","")&IF(AND(OR(TRIM($A10)="Denied",TRIM($A10)="Rejected"),$BA10=""),"Denial Reason, ","")&IF(AND(TRIM($A10)="Denied",$BB10="",TRIM($BA10)<>"NO DENIAL"),"Denial Code, ","")&IF(AND(TRIM($A10)<>"Finalized",$BD10=""),"Next Review Date, ","")&IF(AND(TRIM($A10)<>"Finalized",$BE10=""),"Next Step, ","")&IF(AND(TRIM($A10)="Finalized",$AV10="",$AR10="",$AT10="",$AX10="",$AW10=""),"CPT outcome, ",""),LEN(IF($B10="","Notes, ","")&IF($K10="","Latest Date Worked, ","")&IF($AY10="","Last Action, ","")&IF(AND(OR(TRIM($A10)="Denied",TRIM($A10)="Rejected"),$BA10=""),"Denial Reason, ","")&IF(AND(TRIM($A10)="Denied",$BB10="",TRIM($BA10)<>"NO DENIAL"),"Denial Code, ","")&IF(AND(TRIM($A10)<>"Finalized",$BD10=""),"Next Review Date, ","")&IF(AND(TRIM($A10)<>"Finalized",$BE10=""),"Next Step, ","")&IF(AND(TRIM($A10)="Finalized",$AV10="",$AR10="",$AT10="",$AX10="",$AW10=""),"CPT outcome, ",""))-2),"") | BI10: =IF($BB10="","",IFERROR(INDEX('Denial Codes'!$C:$C,MATCH(LEFT($BB10,FIND(" - ",$BB10&" - ")+2)&"*",'Denial Codes'!$A:$A,0)),"")) | BJ10: =IF($BA10="","",IFERROR(INDEX(Lists!$B:$B,MATCH(TRIM($BA10),Lists!$A:$A,0))&"","")) -> Check the NCCI pair; if the service was distinct, add 59/XU (or XS) and resubmit; otherwise adjust.
A11: Denied | B11: Uploaded MR - Transaction Submission Confirmation Case ID# 18149 | C11: 568312031 | D11: 46266 | E11: HF460572363 | F11: 46126 | G11: UMR Wausau / UHIS | H11: UMR Wausau / UHIS | I11: No Payer | J11: 93970 x1 | K11: 46310 | L11: =IF($O11="","",$O11-TODAY()) | N11: =IF(AND(TRIM($A11)="Finalized",$K11<>""),"",IF($D11="","",$D11+180-TODAY())) -> 135 | Q11: UMR / WAUSAU | T11: 180 days | U11: Processed date | V11: 2026-04 April | W11: US | AA11: 1 | AB11: =IF($F11="","",TODAY()-$F11) -> 185 | AC11: 93970 | AJ11: E1142 | AK11: E7849 | AL11: I10 | AO11: LEATHEM, JARRETT | AP11: ASAP - Gilbert | AQ11: 46245 | AX11: 93970 | AY11: Uploaded MR | BA11: Medical records needed | BB11: CO_252 - An attachment/other documentation is required to adjudicate this claim/service | BC11: Case ID# 18149 | BD11: 46341 | BF11: =IF(TRIM($A11)="Finalized","Closed",IF($BD11="","No review date set",IF($BD11<TODAY(),"OVERDUE",IF($BD11-TODAY()<=7,"Due within 7 days","Scheduled")))) -> Scheduled | BG11: =IF($K11="","",TODAY()-$K11) -> 1 | BH11: =IFERROR(LEFT(IF($B11="","Notes, ","")&IF($K11="","Latest Date Worked, ","")&IF($AY11="","Last Action, ","")&IF(AND(OR(TRIM($A11)="Denied",TRIM($A11)="Rejected"),$BA11=""),"Denial Reason, ","")&IF(AND(TRIM($A11)="Denied",$BB11="",TRIM($BA11)<>"NO DENIAL"),"Denial Code, ","")&IF(AND(TRIM($A11)<>"Finalized",$BD11=""),"Next Review Date, ","")&IF(AND(TRIM($A11)<>"Finalized",$BE11=""),"Next Step, ","")&IF(AND(TRIM($A11)="Finalized",$AV11="",$AR11="",$AT11="",$AX11="",$AW11=""),"CPT outcome, ",""),LEN(IF($B11="","Notes, ","")&IF($K11="","Latest Date Worked, ","")&IF($AY11="","Last Action, ","")&IF(AND(OR(TRIM($A11)="Denied",TRIM($A11)="Rejected"),$BA11=""),"Denial Reason, ","")&IF(AND(TRIM($A11)="Denied",$BB11="",TRIM($BA11)<>"NO DENIAL"),"Denial Code, ","")&IF(AND(TRIM($A11)<>"Finalized",$BD11=""),"Next Review Date, ","")&IF(AND(TRIM($A11)<>"Finalized",$BE11=""),"Next Step, ","")&IF(AND(TRIM($A11)="Finalized",$AV11="",$AR11="",$AT11="",$AX11="",$AW11=""),"CPT outcome, ",""))-2),"") -> Next Step | BI11: =IF($BB11="","",IFERROR(INDEX('Denial Codes'!$C:$C,MATCH(LEFT($BB11,FIND(" - ",$BB11&" - ")+2)&"*",'Denial Codes'!$A:$A,0)),"")) -> Medical records needed | BJ11: =IF($BA11="","",IFERROR(INDEX(Lists!$B:$B,MATCH(TRIM($BA11),Lists!$A:$A,0))&"","")) -> Upload the MR on the payer portal, note the PIQ/reference number and set a review date.
A12: Denied | B12: Uploaded MR on portal | C12: 556730319 | D12: 46279 | E12: HF530285792 | F12: 46127 | G12: Tricare West | H12: Tricare West | I12: No Payer | J12: 63047 x1 | K12: 46311 | L12: =IF($O12="","",$O12-TODAY()) -> 181 | M12: =IF(AND(TRIM($A12)="Finalized",$K12<>""),"",IF($F12="","",$F12+365-TODAY())) -> 181 | N12: =IF(AND(TRIM($A12)="Finalized",$K12<>""),"",IF($D12="","",$D12+90-TODAY())) -> 58 | O12: =IF(AND(TRIM($A12)="Finalized",$K12<>""),"",DATE(2027,4,15)) -> 46492 | P12: 365 days | Q12: TRICARE WEST | R12: 365 days | S12: Date of service | T12: 90 days | U12: Processed date | V12: 2026-04 April | W12: ORTHO | AA12: 1 | AB12: =IF($F12="","",TODAY()-$F12) -> 184 | AC12: 63047 | AJ12: M5416 | AK12: M5450 | AO12: MCCUNNIFF, PETER | AP12: ASAP Surgery Centers North Valley LLC | AQ12: 46246 | AV12: 63048 | AX12: 63047 | AY12: Uploaded MR | BA12: Medical records needed | BB12: CO_252 - An attachment/other documentation is required to adjudicate this claim/service | BD12: 46311 | BF12: =IF(TRIM($A12)="Finalized","Closed",IF($BD12="","No review date set",IF($BD12<TODAY(),"OVERDUE",IF($BD12-TODAY()<=7,"Due within 7 days","Scheduled")))) -> Due within 7 days | BG12: =IF($K12="","",TODAY()-$K12) -> 0 | BH12: =IFERROR(LEFT(IF($B12="","Notes, ","")&IF($K12="","Latest Date Worked, ","")&IF($AY12="","Last Action, ","")&IF(AND(OR(TRIM($A12)="Denied",TRIM($A12)="Rejected"),$BA12=""),"Denial Reason, ","")&IF(AND(TRIM($A12)="Denied",$BB12="",TRIM($BA12)<>"NO DENIAL"),"Denial Code, ","")&IF(AND(TRIM($A12)<>"Finalized",$BD12=""),"Next Review Date, ","")&IF(AND(TRIM($A12)<>"Finalized",$BE12=""),"Next Step, ","")&IF(AND(TRIM($A12)="Finalized",$AV12="",$AR12="",$AT12="",$AX12="",$AW12=""),"CPT outcome, ",""),LEN(IF($B12="","Notes, ","")&IF($K12="","Latest Date Worked, ","")&IF($AY12="","Last Action, ","")&IF(AND(OR(TRIM($A12)="Denied",TRIM($A12)="Rejected"),$BA12=""),"Denial Reason, ","")&IF(AND(TRIM($A12)="Denied",$BB12="",TRIM($BA12)<>"NO DENIAL"),"Denial Code, ","")&IF(AND(TRIM($A12)<>"Finalized",$BD12=""),"Next Review Date, ","")&IF(AND(TRIM($A12)<>"Finalized",$BE12=""),"Next Step, ","")&IF(AND(TRIM($A12)="Finalized",$AV12="",$AR12="",$AT12="",$AX12="",$AW12=""),"CPT outcome, ",""))-2),"") -> Next Step | BI12: =IF($BB12="","",IFERROR(INDEX('Denial Codes'!$C:$C,MATCH(LEFT($BB12,FIND(" - ",$BB12&" - ")+2)&"*",'Denial Codes'!$A:$A,0)),"")) -> Medical records needed | BJ12: =IF($BA12="","",IFERROR(INDEX(Lists!$B:$B,MATCH(TRIM($BA12),Lists!$A:$A,0))&"","")) -> Upload the MR on the payer portal, note the PIQ/reference number and set a review date.
A13: Denied | B13: TFierro30 corrected claim and resubmitted - Filed reconsideration with MR - PIQ-89945925 | C13: 573339755 | D13: 46289 | E13: HF331720981 | F13: 46132 | G13: United Healthcare | H13: United Healthcare | I13: No Payer | J13: 63685 x1 | K13: 46295 | L13: =IF($O13="","",$O13-TODAY()) -> -89 | M13: =IF(AND(TRIM($A13)="Finalized",$K13<>""),"",IF($D13="","",$D13+180-TODAY())) -> 158 | N13: =IF(AND(TRIM($A13)="Finalized",$K13<>""),"",IF($D13="","",$D13+365-TODAY())) -> 343 | O13: =IF(AND(TRIM($A13)="Finalized",$K13<>""),"",DATE(2026,7,19)) -> 46222 | P13: 90 days | Q13: UHC COMMERCIAL | R13: 180 days | S13: Processed date | T13: 365 days | U13: Processed date | V13: 2026-04 April | W13: ORTHO | AA13: 1 | AB13: =IF($F13="","",TODAY()-$F13) -> 179 | AC13: 63685 | AJ13: T85122A | AK13: Z4542 | AL13: M961 | AO13: BURGHER, ABRAM | AP13: ASAP Surgery Centers North Valley LLC | AQ13: 46149 | AX13: 63663, 63685 | AY13: Resubmitted | AZ13: Uploaded MR | BA13: Medical records needed | BB13: CO_50 - Non-covered services because this is not deemed a 'medical necessity' by the payer | BF13: =IF(TRIM($A13)="Finalized","Closed",IF($BD13="","No review date set",IF($BD13<TODAY(),"OVERDUE",IF($BD13-TODAY()<=7,"Due within 7 days","Scheduled")))) -> No review date set | BG13: =IF($K13="","",TODAY()-$K13) -> 16 | BH13: =IFERROR(LEFT(IF($B13="","Notes, ","")&IF($K13="","Latest Date Worked, ","")&IF($AY13="","Last Action, ","")&IF(AND(OR(TRIM($A13)="Denied",TRIM($A13)="Rejected"),$BA13=""),"Denial Reason, ","")&IF(AND(TRIM($A13)="Denied",$BB13="",TRIM($BA13)<>"NO DENIAL"),"Denial Code, ","")&IF(AND(TRIM($A13)<>"Finalized",$BD13=""),"Next Review Date, ","")&IF(AND(TRIM($A13)<>"Finalized",$BE13=""),"Next Step, ","")&IF(AND(TRIM($A13)="Finalized",$AV13="",$AR13="",$AT13="",$AX13="",$AW13=""),"CPT outcome, ",""),LEN(IF($B13="","Notes, ","")&IF($K13="","Latest Date Worked, ","")&IF($AY13="","Last Action, ","")&IF(AND(OR(TRIM($A13)="Denied",TRIM($A13)="Rejected"),$BA13=""),"Denial Reason, ","")&IF(AND(TRIM($A13)="Denied",$BB13="",TRIM($BA13)<>"NO DENIAL"),"Denial Code, ","")&IF(AND(TRIM($A13)<>"Finalized",$BD13=""),"Next Review Date, ","")&IF(AND(TRIM($A13)<>"Finalized",$BE13=""),"Next Step, ","")&IF(AND(TRIM($A13)="Finalized",$AV13="",$AR13="",$AT13="",$AX13="",$AW13=""),"CPT outcome, ",""))-2),"") -> Next Review Date, Next Step | BI13: =IF($BB13="","",IFERROR(INDEX('Denial Codes'!$C:$C,MATCH(LEFT($BB13,FIND(" - ",$BB13&" - ")+2)&"*",'Denial Codes'!$A:$A,0)),"")) -> Medical necessity / frequency | BJ13: =IF($BA13="","",IFERROR(INDEX(Lists!$B:$B,MATCH(TRIM($BA13),Lists!$A:$A,0))&"","")) -> Upload the MR on the payer portal, note the PIQ/reference number and set a review date.
A14: Denied | B14: Resubmitted - RENEE OROC credentialing issue - Denied Remark MA130 Multiple submission/billing errors unable to adjudicate claim as submitted | C14: 557506616 | D14: 46258 | E14: HF508283049 | F14: 46136 | G14: Blue Cross Blue Shield of Arizona (BCBS AZ) | H14: Blue Cross Blue Shield of Arizona (BCBS AZ) | I14: Medicare Part B Arizona * | J14: A6023+A1 x20 | K14: 46310 | L14: =IF($O14="","",$O14-TODAY()) -> -85 | M14: =IF(AND(TRIM($A14)="Finalized",$K14<>""),"",IF($F14="","",$F14+90-TODAY())) -> -85 | N14: =IF(AND(TRIM($A14)="Finalized",$K14<>""),"",IF($D14="","",$D14+365-TODAY())) -> 312 | O14: =IF(AND(TRIM($A14)="Finalized",$K14<>""),"",DATE(2026,7,23)) -> 46226 | P14: 90 days | Q14: BCBS | R14: 90 days | S14: Date of service | T14: 365 days | U14: Processed date | V14: 2026-04 April | W14: DME | X14: A1 | AA14: 20 | AB14: =IF($F14="","",TODAY()-$F14) -> 175 | AC14: A6023 | AJ14: G894 | AK14: M48062 | AO14: OROC, RENEE | AP14: ASAP - Mesa | AQ14: 46254 | AX14: A6023 | AY14: Resubmitted | BA14: Credentialing / out of network | BB14: PR_96 - Non-covered charge(s) | BD14: 46341 | BF14: =IF(TRIM($A14)="Finalized","Closed",IF($BD14="","No review date set",IF($BD14<TODAY(),"OVERDUE",IF($BD14-TODAY()<=7,"Due within 7 days","Scheduled")))) -> Scheduled | BG14: =IF($K14="","",TODAY()-$K14) -> 1 | BH14: =IFERROR(LEFT(IF($B14="","Notes, ","")&IF($K14="","Latest Date Worked, ","")&IF($AY14="","Last Action, ","")&IF(AND(OR(TRIM($A14)="Denied",TRIM($A14)="Rejected"),$BA14=""),"Denial Reason, ","")&IF(AND(TRIM($A14)="Denied",$BB14="",TRIM($BA14)<>"NO DENIAL"),"Denial Code, ","")&IF(AND(TRIM($A14)<>"Finalized",$BD14=""),"Next Review Date, ","")&IF(AND(TRIM($A14)<>"Finalized",$BE14=""),"Next Step, ","")&IF(AND(TRIM($A14)="Finalized",$AV14="",$AR14="",$AT14="",$AX14="",$AW14=""),"CPT outcome, ",""),LEN(IF($B14="","Notes, ","")&IF($K14="","Latest Date Worked, ","")&IF($AY14="","Last Action, ","")&IF(AND(OR(TRIM($A14)="Denied",TRIM($A14)="Rejected"),$BA14=""),"Denial Reason, ","")&IF(AND(TRIM($A14)="Denied",$BB14="",TRIM($BA14)<>"NO DENIAL"),"Denial Code, ","")&IF(AND(TRIM($A14)<>"Finalized",$BD14=""),"Next Review Date, ","")&IF(AND(TRIM($A14)<>"Finalized",$BE14=""),"Next Step, ","")&IF(AND(TRIM($A14)="Finalized",$AV14="",$AR14="",$AT14="",$AX14="",$AW14=""),"CPT outcome, ",""))-2),"") -> Next Step | BI14: =IF($BB14="","",IFERROR(INDEX('Denial Codes'!$C:$C,MATCH(LEFT($BB14,FIND(" - ",$BB14&" - ")+2)&"*",'Denial Codes'!$A:$A,0)),"")) -> Not covered by plan | BJ14: =IF($BA14="","",IFERROR(INDEX(Lists!$B:$B,MATCH(TRIM($BA14),Lists!$A:$A,0))&"","")) -> Check provider enrollment, NPI/TIN and network status; appeal once credentialing is confirmed.
A15: Denied | B15: Edited referring provider, and resubmitted | C15: 568470154 | D15: 46253 | E15: HF474490292 | F15: 46148 | G15: Medicare Part B Arizona * | H15: Medicare Part B Arizona * | I15: Tricare for Life (All Regions) | J15: 93970 x1 | K15: 46310 | L15: =IF($O15="","",$O15-TODAY()) -> 202 | M15: =IF(AND(TRIM($A15)="Finalized",$K15<>""),"",IF($D15="","",$D15+365-TODAY())) -> 307 | N15: =IF(AND(TRIM($A15)="Finalized",$K15<>""),"",IF($D15="","",$D15+120-TODAY())) -> 62 | O15: =IF(AND(TRIM($A15)="Finalized",$K15<>""),"",DATE(2027,5,6)) -> 46513 | P15: 365 days | Q15: MEDICARE | R15: 365 days | S15: Processed date | T15: 120 days | U15: Processed date | V15: 2026-05 May | W15: US | AA15: 1 | AB15: =IF($F15="","",TODAY()-$F15) -> 163 | AC15: 93970 | AJ15: I872 | AO15: BURGHER, ABRAM | AP15: ASAP - Surprise - Reems | AQ15: 46246 | AX15: 93970 | AY15: Resubmitted | BA15: Referral / referring provider | BB15: CO_183 - The referring provider is not eligible to refer the service billed | BD15: 46341 | BF15: =IF(TRIM($A15)="Finalized","Closed",IF($BD15="","No review date set",IF($BD15<TODAY(),"OVERDUE",IF($BD15-TODAY()<=7,"Due within 7 days","Scheduled")))) -> Scheduled | BG15: =IF($K15="","",TODAY()-$K15) -> 1 | BH15: =IFERROR(LEFT(IF($B15="","Notes, ","")&IF($K15="","Latest Date Worked, ","")&IF($AY15="","Last Action, ","")&IF(AND(OR(TRIM($A15)="Denied",TRIM($A15)="Rejected"),$BA15=""),"Denial Reason, ","")&IF(AND(TRIM($A15)="Denied",$BB15="",TRIM($BA15)<>"NO DENIAL"),"Denial Code, ","")&IF(AND(TRIM($A15)<>"Finalized",$BD15=""),"Next Review Date, ","")&IF(AND(TRIM($A15)<>"Finalized",$BE15=""),"Next Step, ","")&IF(AND(TRIM($A15)="Finalized",$AV15="",$AR15="",$AT15="",$AX15="",$AW15=""),"CPT outcome, ",""),LEN(IF($B15="","Notes, ","")&IF($K15="","Latest Date Worked, ","")&IF($AY15="","Last Action, ","")&IF(AND(OR(TRIM($A15)="Denied",TRIM($A15)="Rejected"),$BA15=""),"Denial Reason, ","")&IF(AND(TRIM($A15)="Denied",$BB15="",TRIM($BA15)<>"NO DENIAL"),"Denial Code, ","")&IF(AND(TRIM($A15)<>"Finalized",$BD15=""),"Next Review Date, ","")&IF(AND(TRIM($A15)<>"Finalized",$BE15=""),"Next Step, ","")&IF(AND(TRIM($A15)="Finalized",$AV15="",$AR15="",$AT15="",$AX15="",$AW15=""),"CPT outcome, ",""))-2),"") -> Next Step | BI15: =IF($BB15="","",IFERROR(INDEX('Denial Codes'!$C:$C,MATCH(LEFT($BB15,FIND(" - ",$BB15&" - ")+2)&"*",'Denial Codes'!$A:$A,0)),"")) -> Referral / referring provider | BJ15: =IF($BA15="","",IFERROR(INDEX(Lists!$B:$B,MATCH(TRIM($BA15),Lists!$A:$A,0))&"","")) -> Get a valid referral or correct the referring provider, then resubmit.
A16: Denied | B16: Waiting on full recoup to bill PT - ABN signed - Bundling with HHA episode on DOS - HOME HEALTH SCOTTSDALE, LLC NPI 1154898542 | C16: 559112760 | D16: 46218 | E16: HF550801271 | F16: 46149 | G16: AARP United Healthcare | H16: DME Region D | I16: AARP United Healthcare | J16: A6010+A1 x10 | L16: =IF($O16="","",$O16-TODAY()) -> 203 | M16: =IF(AND(TRIM($A16)="Finalized",$K16<>""),"",IF($D16="","",$D16+365-TODAY())) -> 272 | N16: =IF(AND(TRIM($A16)="Finalized",$K16<>""),"",IF($D16="","",$D16+120-TODAY())) -> 27 | O16: =IF(AND(TRIM($A16)="Finalized",$K16<>""),"",DATE(2027,5,7)) -> 46514 | P16: 365 days | Q16: MEDICARE | R16: 365 days | S16: Processed date | T16: 120 days | U16: Processed date | V16: 2026-05 May | W16: DME | X16: A1 | AA16: 10 | AB16: =IF($F16="","",TODAY()-$F16) -> 162 | AC16: A6010 | AJ16: G894 | AK16: M5416 | AL16: M48062 | AN16: 561539073 | AO16: Advanced Spine and Pain LLC DME GWY | AP16: Advanced Spine and Pain LLC DME - Greenway | AQ16: 46155 | AX16: A6010 | BA16: Bundled / NCCI edit | BB16: N88 Alert: This payment is being made conditionally. An HHA episode of care notice has been filed for this patient. When a patient is treated under a HHA episode of care, consolidated billing requires that certain therapy services and supplies, such as this, be included in the HHA's payment. This payment will need to be recouped from you if we establish that the patient is concurrently receiving treatment under a HHA episode of care | BE16: Waiting on full recoup to bill PT | BF16: =IF(TRIM($A16)="Finalized","Closed",IF($BD16="","No review date set",IF($BD16<TODAY(),"OVERDUE",IF($BD16-TODAY()<=7,"Due within 7 days","Scheduled")))) -> No review date set | BG16: =IF($K16="","",TODAY()-$K16) | BH16: =IFERROR(LEFT(IF($B16="","Notes, ","")&IF($K16="","Latest Date Worked, ","")&IF($AY16="","Last Action, ","")&IF(AND(OR(TRIM($A16)="Denied",TRIM($A16)="Rejected"),$BA16=""),"Denial Reason, ","")&IF(AND(TRIM($A16)="Denied",$BB16="",TRIM($BA16)<>"NO DENIAL"),"Denial Code, ","")&IF(AND(TRIM($A16)<>"Finalized",$BD16=""),"Next Review Date, ","")&IF(AND(TRIM($A16)<>"Finalized",$BE16=""),"Next Step, ","")&IF(AND(TRIM($A16)="Finalized",$AV16="",$AR16="",$AT16="",$AX16="",$AW16=""),"CPT outcome, ",""),LEN(IF($B16="","Notes, ","")&IF($K16="","Latest Date Worked, ","")&IF($AY16="","Last Action, ","")&IF(AND(OR(TRIM($A16)="Denied",TRIM($A16)="Rejected"),$BA16=""),"Denial Reason, ","")&IF(AND(TRIM($A16)="Denied",$BB16="",TRIM($BA16)<>"NO DENIAL"),"Denial Code, ","")&IF(AND(TRIM($A16)<>"Finalized",$BD16=""),"Next Review Date, ","")&IF(AND(TRIM($A16)<>"Finalized",$BE16=""),"Next Step, ","")&IF(AND(TRIM($A16)="Finalized",$AV16="",$AR16="",$AT16="",$AX16="",$AW16=""),"CPT outcome, ",""))-2),"") -> Latest Date Worked, Last Action, Next Review Date | BI16: =IF($BB16="","",IFERROR(INDEX('Denial Codes'!$C:$C,MATCH(LEFT($BB16,FIND(" - ",$BB16&" - ")+2)&"*",'Denial Codes'!$A:$A,0)),"")) | BJ16: =IF($BA16="","",IFERROR(INDEX(Lists!$B:$B,MATCH(TRIM($BA16),Lists!$A:$A,0))&"","")) -> Check the NCCI pair; if the service was distinct, add 59/XU (or XS) and resubmit; otherwise adjust.
A17: Rejected | B17: Rejected due to invalid/missing modifier | C17: 560559053 | E17: WC-559349596 | F17: 46168 | G17: Arizona Complete Health (Centene) | H17: Arizona Complete Health (Centene) | I17: No Payer | J17: 99484+95 x1 | L17: =IF($O17="","",$O17-TODAY()) -> -23 | M17: =IF(AND(TRIM($A17)="Finalized",$K17<>""),"",IF($F17="","",$F17+365-TODAY())) -> 222 | N17: =IF(AND(TRIM($A17)="Finalized",$K17<>""),"",IF($F17="","",$F17+365-TODAY())) -> 222 | O17: =IF(AND(TRIM($A17)="Finalized",$K17<>""),"",DATE(2026,9,23)) -> 46288 | P17: 120 days | Q17: AZ COMPLETE | R17: 365 days | S17: Date of service | T17: 365 days | U17: Date of service | V17: 2026-05 May | W17: BH | X17: 95 | AA17: 1 | AB17: =IF($F17="","",TODAY()-$F17) -> 143 | AC17: 99484 | AJ17: M5412 | AK17: M5416 | AL17: Z79891 | AM17: Z1331 | AO17: WILSON, JARED | AP17: ASAP - Gilbert | AQ17: 46275 | AX17: 99204, 99484 | BA17: Modifier issue | BE17: Waiting for D's reply | BF17: =IF(TRIM($A17)="Finalized","Closed",IF($BD17="","No review date set",IF($BD17<TODAY(),"OVERDUE",IF($BD17-TODAY()<=7,"Due within 7 days","Scheduled")))) -> No review date set | BG17: =IF($K17="","",TODAY()-$K17) | BH17: =IFERROR(LEFT(IF($B17="","Notes, ","")&IF($K17="","Latest Date Worked, ","")&IF($AY17="","Last Action, ","")&IF(AND(OR(TRIM($A17)="Denied",TRIM($A17)="Rejected"),$BA17=""),"Denial Reason, ","")&IF(AND(TRIM($A17)="Denied",$BB17="",TRIM($BA17)<>"NO DENIAL"),"Denial Code, ","")&IF(AND(TRIM($A17)<>"Finalized",$BD17=""),"Next Review Date, ","")&IF(AND(TRIM($A17)<>"Finalized",$BE17=""),"Next Step, ","")&IF(AND(TRIM($A17)="Finalized",$AV17="",$AR17="",$AT17="",$AX17="",$AW17=""),"CPT outcome, ",""),LEN(IF($B17="","Notes, ","")&IF($K17="","Latest Date Worked, ","")&IF($AY17="","Last Action, ","")&IF(AND(OR(TRIM($A17)="Denied",TRIM($A17)="Rejected"),$BA17=""),"Denial Reason, ","")&IF(AND(TRIM($A17)="Denied",$BB17="",TRIM($BA17)<>"NO DENIAL"),"Denial Code, ","")&IF(AND(TRIM($A17)<>"Finalized",$BD17=""),"Next Review Date, ","")&IF(AND(TRIM($A17)<>"Finalized",$BE17=""),"Next Step, ","")&IF(AND(TRIM($A17)="Finalized",$AV17="",$AR17="",$AT17="",$AX17="",$AW17=""),"CPT outcome, ",""))-2),"") -> Latest Date Worked, Last Action, Next Review Date | BI17: =IF($BB17="","",IFERROR(INDEX('Denial Codes'!$C:$C,MATCH(LEFT($BB17,FIND(" - ",$BB17&" - ")+2)&"*",'Denial Codes'!$A:$A,0)),"")) | BJ17: =IF($BA17="","",IFERROR(INDEX(Lists!$B:$B,MATCH(TRIM($BA17),Lists!$A:$A,0))&"","")) -> Correct or add the modifier (e.g. NU/RR, KX, RT/LT, 25) and resubmit.
A18: Rejected | B18: Rejected due to invalid/missing modifier | C18: 560607909 | E18: HF559630348 | F18: 46169 | G18: Arizona Complete Health (Centene) | H18: Arizona Complete Health (Centene) | I18: No Payer | J18: 99484+95 x1 | L18: =IF($O18="","",$O18-TODAY()) -> -22 | M18: =IF(AND(TRIM($A18)="Finalized",$K18<>""),"",IF($F18="","",$F18+365-TODAY())) -> 223 | N18: =IF(AND(TRIM($A18)="Finalized",$K18<>""),"",IF($F18="","",$F18+365-TODAY())) -> 223 | O18: =IF(AND(TRIM($A18)="Finalized",$K18<>""),"",DATE(2026,9,24)) -> 46289 | P18: 120 days | Q18: AZ COMPLETE | R18: 365 days | S18: Date of service | T18: 365 days | U18: Date of service | V18: 2026-05 May | W18: BH | X18: 95 | AA18: 1 | AB18: =IF($F18="","",TODAY()-$F18) -> 142 | AC18: 99484 | AJ18: M546 | AK18: M542 | AL18: Z79891 | AM18: Z1331 | AO18: WILSON, JARED | AP18: ASAP - Gilbert | AQ18: 46275 | AX18: 99204, 99484 | BA18: Modifier issue | BE18: Waiting for D's reply | BF18: =IF(TRIM($A18)="Finalized","Closed",IF($BD18="","No review date set",IF($BD18<TODAY(),"OVERDUE",IF($BD18-TODAY()<=7,"Due within 7 days","Scheduled")))) -> No review date set | BG18: =IF($K18="","",TODAY()-$K18) | BH18: =IFERROR(LEFT(IF($B18="","Notes, ","")&IF($K18="","Latest Date Worked, ","")&IF($AY18="","Last Action, ","")&IF(AND(OR(TRIM($A18)="Denied",TRIM($A18)="Rejected"),$BA18=""),"Denial Reason, ","")&IF(AND(TRIM($A18)="Denied",$BB18="",TRIM($BA18)<>"NO DENIAL"),"Denial Code, ","")&IF(AND(TRIM($A18)<>"Finalized",$BD18=""),"Next Review Date, ","")&IF(AND(TRIM($A18)<>"Finalized",$BE18=""),"Next Step, ","")&IF(AND(TRIM($A18)="Finalized",$AV18="",$AR18="",$AT18="",$AX18="",$AW18=""),"CPT outcome, ",""),LEN(IF($B18="","Notes, ","")&IF($K18="","Latest Date Worked, ","")&IF($AY18="","Last Action, ","")&IF(AND(OR(TRIM($A18)="Denied",TRIM($A18)="Rejected"),$BA18=""),"Denial Reason, ","")&IF(AND(TRIM($A18)="Denied",$BB18="",TRIM($BA18)<>"NO DENIAL"),"Denial Code, ","")&IF(AND(TRIM($A18)<>"Finalized",$BD18=""),"Next Review Date, ","")&IF(AND(TRIM($A18)<>"Finalized",$BE18=""),"Next Step, ","")&IF(AND(TRIM($A18)="Finalized",$AV18="",$AR18="",$AT18="",$AX18="",$AW18=""),"CPT outcome, ",""))-2),"") -> Latest Date Worked, Last Action, Next Review Date | BI18: =IF($BB18="","",IFERROR(INDEX('Denial Codes'!$C:$C,MATCH(LEFT($BB18,FIND(" - ",$BB18&" - ")+2)&"*",'Denial Codes'!$A:$A,0)),"")) | BJ18: =IF($BA18="","",IFERROR(INDEX(Lists!$B:$B,MATCH(TRIM($BA18),Lists!$A:$A,0))&"","")) -> Correct or add the modifier (e.g. NU/RR, KX, RT/LT, 25) and resubmit.
A19: Denied | B19: Checking with D to see if I adjust or ask scriber to adjust | C19: 570821252 | D19: 46279 | E19: HF559271506 | F19: 46169 | G19: Medicare Part B Arizona * | H19: Medicare Part B Arizona * | I19: No Payer | J19: 99484+95 x1 | L19: =IF($O19="","",$O19-TODAY()) -> 223 | M19: =IF(AND(TRIM($A19)="Finalized",$K19<>""),"",IF($D19="","",$D19+365-TODAY())) -> 333 | N19: =IF(AND(TRIM($A19)="Finalized",$K19<>""),"",IF($D19="","",$D19+120-TODAY())) -> 88 | O19: =IF(AND(TRIM($A19)="Finalized",$K19<>""),"",DATE(2027,5,27)) -> 46534 | P19: 365 days | Q19: MEDICARE | R19: 365 days | S19: Processed date | T19: 120 days | U19: Processed date | V19: 2026-05 May | W19: BH | X19: 95 | AA19: 1 | AB19: =IF($F19="","",TODAY()-$F19) -> 142 | AC19: 99484 | AJ19: G894 | AK19: M961 | AL19: Z79891 | AM19: Z1331 | AO19: WILSON, JARED | AP19: ASAP - Gilbert | AQ19: 46268 | AX19: 99204, 99484 | BA19: Medical necessity / frequency | BB19: N776 - This service is not a covered Telehealth service | BE19: Waiting for D's reply | BF19: =IF(TRIM($A19)="Finalized","Closed",IF($BD19="","No review date set",IF($BD19<TODAY(),"OVERDUE",IF($BD19-TODAY()<=7,"Due within 7 days","Scheduled")))) -> No review date set | BG19: =IF($K19="","",TODAY()-$K19) | BH19: =IFERROR(LEFT(IF($B19="","Notes, ","")&IF($K19="","Latest Date Worked, ","")&IF($AY19="","Last Action, ","")&IF(AND(OR(TRIM($A19)="Denied",TRIM($A19)="Rejected"),$BA19=""),"Denial Reason, ","")&IF(AND(TRIM($A19)="Denied",$BB19="",TRIM($BA19)<>"NO DENIAL"),"Denial Code, ","")&IF(AND(TRIM($A19)<>"Finalized",$BD19=""),"Next Review Date, ","")&IF(AND(TRIM($A19)<>"Finalized",$BE19=""),"Next Step, ","")&IF(AND(TRIM($A19)="Finalized",$AV19="",$AR19="",$AT19="",$AX19="",$AW19=""),"CPT outcome, ",""),LEN(IF($B19="","Notes, ","")&IF($K19="","Latest Date Worked, ","")&IF($AY19="","Last Action, ","")&IF(AND(OR(TRIM($A19)="Denied",TRIM($A19)="Rejected"),$BA19=""),"Denial Reason, ","")&IF(AND(TRIM($A19)="Denied",$BB19="",TRIM($BA19)<>"NO DENIAL"),"Denial Code, ","")&IF(AND(TRIM($A19)<>"Finalized",$BD19=""),"Next Review Date, ","")&IF(AND(TRIM($A19)<>"Finalized",$BE19=""),"Next Step, ","")&IF(AND(TRIM($A19)="Finalized",$AV19="",$AR19="",$AT19="",$AX19="",$AW19=""),"CPT outcome, ",""))-2),"") -> Latest Date Worked, Last Action, Next Review Date | BI19: =IF($BB19="","",IFERROR(INDEX('Denial Codes'!$C:$C,MATCH(LEFT($BB19,FIND(" - ",$BB19&" - ")+2)&"*",'Denial Codes'!$A:$A,0)),"")) -> Not covered by plan | BJ19: =IF($BA19="","",IFERROR(INDEX(Lists!$B:$B,MATCH(TRIM($BA19),Lists!$A:$A,0))&"","")) -> Appeal with medical records and a letter of medical necessity; check LCD/MUE limits.
A20: Under Review | B20: I need to confirm with D if 99204 would be adjusted or we can change the encounter notes | C20: 560610028 | D20: 46283 | E20: HF559317309 | F20: 46169 | G20: Medicare Part B Arizona * | H20: Medicare Part B Arizona * | I20: Blue Cross Blue Shield of Arizona (BCBS AZ) | J20: 99484+95 x1 | L20: =IF($O20="","",$O20-TODAY()) -> 223 | M20: =IF(AND(TRIM($A20)="Finalized",$K20<>""),"",IF($D20="","",$D20+365-TODAY())) -> 337 | N20: =IF(AND(TRIM($A20)="Finalized",$K20<>""),"",IF($D20="","",$D20+120-TODAY())) -> 92 | O20: =IF(AND(TRIM($A20)="Finalized",$K20<>""),"",DATE(2027,5,27)) -> 46534 | P20: 365 days | Q20: MEDICARE | R20: 365 days | S20: Processed date | T20: 120 days | U20: Processed date | V20: 2026-05 May | W20: BH | X20: 95 | AA20: 1 | AB20: =IF($F20="","",TODAY()-$F20) -> 142 | AC20: 99484 | AJ20: G894 | AK20: M4804 | AL20: M961 | AM20: K5903 | AO20: WILSON, JARED | AP20: ASAP - Gilbert | AQ20: 46275 | AT20: 99204 | AU20: CO_151 - Payer deems the information submitted does not support this many/frequency of services | AX20: 99204, 99484 | BA20: Medical necessity / frequency | BB20: CO_151 - Payer deems the information submitted does not support this many/frequency of services | BD20: 46310 | BE20: I need to confirm with D if 99204 would be adjusted or we can change the encounter notes - if I can resubmit with 99214 I need to bill with POS 11 and remove mod 95 | BF20: =IF(TRIM($A20)="Finalized","Closed",IF($BD20="","No review date set",IF($BD20<TODAY(),"OVERDUE",IF($BD20-TODAY()<=7,"Due within 7 days","Scheduled")))) -> OVERDUE | BG20: =IF($K20="","",TODAY()-$K20) | BH20: =IFERROR(LEFT(IF($B20="","Notes, ","")&IF($K20="","Latest Date Worked, ","")&IF($AY20="","Last Action, ","")&IF(AND(OR(TRIM($A20)="Denied",TRIM($A20)="Rejected"),$BA20=""),"Denial Reason, ","")&IF(AND(TRIM($A20)="Denied",$BB20="",TRIM($BA20)<>"NO DENIAL"),"Denial Code, ","")&IF(AND(TRIM($A20)<>"Finalized",$BD20=""),"Next Review Date, ","")&IF(AND(TRIM($A20)<>"Finalized",$BE20=""),"Next Step, ","")&IF(AND(TRIM($A20)="Finalized",$AV20="",$AR20="",$AT20="",$AX20="",$AW20=""),"CPT outcome, ",""),LEN(IF($B20="","Notes, ","")&IF($K20="","Latest Date Worked, ","")&IF($AY20="","Last Action, ","")&IF(AND(OR(TRIM($A20)="Denied",TRIM($A20)="Rejected"),$BA20=""),"Denial Reason, ","")&IF(AND(TRIM($A20)="Denied",$BB20="",TRIM($BA20)<>"NO DENIAL"),"Denial Code, ","")&IF(AND(TRIM($A20)<>"Finalized",$BD20=""),"Next Review Date, ","")&IF(AND(TRIM($A20)<>"Finalized",$BE20=""),"Next Step, ","")&IF(AND(TRIM($A20)="Finalized",$AV20="",$AR20="",$AT20="",$AX20="",$AW20=""),"CPT outcome, ",""))-2),"") -> Latest Date Worked, Last Action | BI20: =IF($BB20="","",IFERROR(INDEX('Denial Codes'!$C:$C,MATCH(LEFT($BB20,FIND(" - ",$BB20&" - ")+2)&"*",'Denial Codes'!$A:$A,0)),"")) -> Medical necessity / frequency | BJ20: =IF($BA20="","",IFERROR(INDEX(Lists!$B:$B,MATCH(TRIM($BA20),Lists!$A:$A,0))&"","")) -> Appeal with medical records and a letter of medical necessity; check LCD/MUE limits.
A21: PAID | B21: OP | C21: 562125174 | D21: 46280 | E21: HF480446510 | F21: 46175 | G21: Blue Cross Blue Shield of Arizona (BCBS AZ) | H21: Blue Cross Blue Shield of Arizona (BCBS AZ) | I21: No Payer | J21: L0637+KX x1 | L21: =IF($O21="","",$O21-TODAY()) -> -46 | M21: =IF(AND(TRIM($A21)="Finalized",$K21<>""),"",IF($F21="","",$F21+90-TODAY())) -> -46 | N21: =IF(AND(TRIM($A21)="Finalized",$K21<>""),"",IF($D21="","",$D21+365-TODAY())) -> 334 | O21: =IF(AND(TRIM($A21)="Finalized",$K21<>""),"",DATE(2026,8,31)) -> 46265 | P21: 90 days | Q21: BCBS | R21: 90 days | S21: Date of service | T21: 365 days | U21: Processed date | V21: 2026-06 June | W21: DME | X21: KX | AA21: 1 | AB21: =IF($F21="","",TODAY()-$F21) -> 136 | AC21: L0637 | AJ21: M47816 | AO21: BARCOME, MARYBETH | AP21: ASAP Peoria | AQ21: 46185 | AV21: L0637 | BE21: We need to renfund BCBS | BF21: =IF(TRIM($A21)="Finalized","Closed",IF($BD21="","No review date set",IF($BD21<TODAY(),"OVERDUE",IF($BD21-TODAY()<=7,"Due within 7 days","Scheduled")))) -> No review date set | BG21: =IF($K21="","",TODAY()-$K21) | BH21: =IFERROR(LEFT(IF($B21="","Notes, ","")&IF($K21="","Latest Date Worked, ","")&IF($AY21="","Last Action, ","")&IF(AND(OR(TRIM($A21)="Denied",TRIM($A21)="Rejected"),$BA21=""),"Denial Reason, ","")&IF(AND(TRIM($A21)="Denied",$BB21="",TRIM($BA21)<>"NO DENIAL"),"Denial Code, ","")&IF(AND(TRIM($A21)<>"Finalized",$BD21=""),"Next Review Date, ","")&IF(AND(TRIM($A21)<>"Finalized",$BE21=""),"Next Step, ","")&IF(AND(TRIM($A21)="Finalized",$AV21="",$AR21="",$AT21="",$AX21="",$AW21=""),"CPT outcome, ",""),LEN(IF($B21="","Notes, ","")&IF($K21="","Latest Date Worked, ","")&IF($AY21="","Last Action, ","")&IF(AND(OR(TRIM($A21)="Denied",TRIM($A21)="Rejected"),$BA21=""),"Denial Reason, ","")&IF(AND(TRIM($A21)="Denied",$BB21="",TRIM($BA21)<>"NO DENIAL"),"Denial Code, ","")&IF(AND(TRIM($A21)<>"Finalized",$BD21=""),"Next Review Date, ","")&IF(AND(TRIM($A21)<>"Finalized",$BE21=""),"Next Step, ","")&IF(AND(TRIM($A21)="Finalized",$AV21="",$AR21="",$AT21="",$AX21="",$AW21=""),"CPT outcome, ",""))-2),"") -> Latest Date Worked, Last Action, Next Review Date | BI21: =IF($BB21="","",IFERROR(INDEX('Denial Codes'!$C:$C,MATCH(LEFT($BB21,FIND(" - ",$BB21&" - ")+2)&"*",'Denial Codes'!$A:$A,0)),"")) | BJ21: =IF($BA21="","",IFERROR(INDEX(Lists!$B:$B,MATCH(TRIM($BA21),Lists!$A:$A,0))&"",""))
A22: PAID | B22: OP | C22: 563181415 | D22: 46258 | E22: HF537547660 | F22: 46195 | G22: Blue Cross Blue Shield of Arizona (BCBS AZ) | H22: Blue Cross Blue Shield of Arizona (BCBS AZ) | I22: No Payer | J22: L0637+KX x1 | L22: =IF($O22="","",$O22-TODAY()) -> -26 | M22: =IF(AND(TRIM($A22)="Finalized",$K22<>""),"",IF($F22="","",$F22+90-TODAY())) -> -26 | N22: =IF(AND(TRIM($A22)="Finalized",$K22<>""),"",IF($D22="","",$D22+365-TODAY())) -> 312 | O22: =IF(AND(TRIM($A22)="Finalized",$K22<>""),"",DATE(2026,9,20)) -> 46285 | P22: 90 days | Q22: BCBS | R22: 90 days | S22: Date of service | T22: 365 days | U22: Processed date | V22: 2026-06 June | W22: DME | X22: KX | AA22: 1 | AB22: =IF($F22="","",TODAY()-$F22) -> 116 | AC22: L0637 | AJ22: M5416 | AK22: M5116 | AL22: M48061 | AO22: TURLEY, TODD | AP22: ASAP - DEER VALLEY | AQ22: 46196 | AV22: L0637 | BE22: We need to renfund BCBS | BF22: =IF(TRIM($A22)="Finalized","Closed",IF($BD22="","No review date set",IF($BD22<TODAY(),"OVERDUE",IF($BD22-TODAY()<=7,"Due within 7 days","Scheduled")))) -> No review date set | BG22: =IF($K22="","",TODAY()-$K22) | BH22: =IFERROR(LEFT(IF($B22="","Notes, ","")&IF($K22="","Latest Date Worked, ","")&IF($AY22="","Last Action, ","")&IF(AND(OR(TRIM($A22)="Denied",TRIM($A22)="Rejected"),$BA22=""),"Denial Reason, ","")&IF(AND(TRIM($A22)="Denied",$BB22="",TRIM($BA22)<>"NO DENIAL"),"Denial Code, ","")&IF(AND(TRIM($A22)<>"Finalized",$BD22=""),"Next Review Date, ","")&IF(AND(TRIM($A22)<>"Finalized",$BE22=""),"Next Step, ","")&IF(AND(TRIM($A22)="Finalized",$AV22="",$AR22="",$AT22="",$AX22="",$AW22=""),"CPT outcome, ",""),LEN(IF($B22="","Notes, ","")&IF($K22="","Latest Date Worked, ","")&IF($AY22="","Last Action, ","")&IF(AND(OR(TRIM($A22)="Denied",TRIM($A22)="Rejected"),$BA22=""),"Denial Reason, ","")&IF(AND(TRIM($A22)="Denied",$BB22="",TRIM($BA22)<>"NO DENIAL"),"Denial Code, ","")&IF(AND(TRIM($A22)<>"Finalized",$BD22=""),"Next Review Date, ","")&IF(AND(TRIM($A22)<>"Finalized",$BE22=""),"Next Step, ","")&IF(AND(TRIM($A22)="Finalized",$AV22="",$AR22="",$AT22="",$AX22="",$AW22=""),"CPT outcome, ",""))-2),"") -> Latest Date Worked, Last Action, Next Review Date | BI22: =IF($BB22="","",IFERROR(INDEX('Denial Codes'!$C:$C,MATCH(LEFT($BB22,FIND(" - ",$BB22&" - ")+2)&"*",'Denial Codes'!$A:$A,0)),"")) | BJ22: =IF($BA22="","",IFERROR(INDEX(Lists!$B:$B,MATCH(TRIM($BA22),Lists!$A:$A,0))&"",""))
